[2024-12-10T08:11:27.222+0000] {local_task_job_runner.py:123} INFO - ::group::Pre task execution logs
[2024-12-10T08:11:27.233+0000] {taskinstance.py:2613} INFO - Dependencies all met for dep_context=non-requeueable deps ti=<TaskInstance: call_9868205040_2024-12-10T08-09-42-184987Z.find_reason_for_unanswered scheduled__2024-12-10T08:09:42.184987+00:00 [queued]>
[2024-12-10T08:11:27.237+0000] {taskinstance.py:2613} INFO - Dependencies all met for dep_context=requeueable deps ti=<TaskInstance: call_9868205040_2024-12-10T08-09-42-184987Z.find_reason_for_unanswered scheduled__2024-12-10T08:09:42.184987+00:00 [queued]>
[2024-12-10T08:11:27.237+0000] {taskinstance.py:2866} INFO - Starting attempt 2 of 2
[2024-12-10T08:11:27.242+0000] {taskinstance.py:2889} INFO - Executing <Task(_PythonDecoratedOperator): find_reason_for_unanswered> on 2024-12-10 08:09:42.184987+00:00
[2024-12-10T08:11:27.247+0000] {warnings.py:112} WARNING - /home/***/.local/lib/python3.12/site-packages/***/task/task_runner/standard_task_runner.py:70: DeprecationWarning: This process (pid=2015) is multi-threaded, use of fork() may lead to deadlocks in the child.
  pid = os.fork()

[2024-12-10T08:11:27.248+0000] {standard_task_runner.py:72} INFO - Started process 2016 to run task
[2024-12-10T08:11:27.249+0000] {standard_task_runner.py:104} INFO - Running: ['***', 'tasks', 'run', 'call_9868205040_2024-12-10T08-09-42-184987Z', 'find_reason_for_unanswered', 'scheduled__2024-12-10T08:09:42.184987+00:00', '--job-id', '360', '--raw', '--subdir', 'DAGS_FOLDER/complete_dag.py', '--cfg-path', '/tmp/tmp_qtp4o77']
[2024-12-10T08:11:27.249+0000] {standard_task_runner.py:105} INFO - Job 360: Subtask find_reason_for_unanswered
[2024-12-10T08:11:27.271+0000] {task_command.py:467} INFO - Running <TaskInstance: call_9868205040_2024-12-10T08-09-42-184987Z.find_reason_for_unanswered scheduled__2024-12-10T08:09:42.184987+00:00 [running]> on host 1868de310944
[2024-12-10T08:11:27.310+0000] {taskinstance.py:3132} INFO - Exporting env vars: AIRFLOW_CTX_DAG_OWNER='***' AIRFLOW_CTX_DAG_ID='call_9868205040_2024-12-10T08-09-42-184987Z' AIRFLOW_CTX_TASK_ID='find_reason_for_unanswered' AIRFLOW_CTX_EXECUTION_DATE='2024-12-10T08:09:42.184987+00:00' AIRFLOW_CTX_TRY_NUMBER='2' AIRFLOW_CTX_DAG_RUN_ID='scheduled__2024-12-10T08:09:42.184987+00:00'
[2024-12-10T08:11:27.310+0000] {taskinstance.py:731} INFO - ::endgroup::
[2024-12-10T08:11:27.312+0000] {logging_mixin.py:190} INFO - demo-scheduled-from-ui-bnbdb6ed36a-b807-4eea-a8e2-76370f3bee30
[2024-12-10T08:11:27.312+0000] {logging_mixin.py:190} INFO - cause_txt: busy
[2024-12-10T08:11:27.316+0000] {base.py:84} INFO - Retrieving connection 'aicallagent'
[2024-12-10T08:11:27.321+0000] {sql.py:544} INFO - Running statement: UPDATE user_details SET status = busy, modified_on_utc = now() at time zone 'utc' WHERE caller_id = 'demo-scheduled-from-ui-bnbdb6ed36a-b807-4eea-a8e2-76370f3bee30', parameters: None
[2024-12-10T08:11:27.322+0000] {taskinstance.py:3311} ERROR - Task failed with exception
Traceback (most recent call last):
  File "/home/airflow/.local/lib/python3.12/site-packages/airflow/models/taskinstance.py", line 767, in _execute_task
    result = _execute_callable(context=context, **execute_callable_kwargs)
             ^^^^^^^^^^^^^^^^^^^^^^^^^^^^^^^^^^^^^^^^^^^^^^^^^^^^^^^^^^^^^
  File "/home/airflow/.local/lib/python3.12/site-packages/airflow/models/taskinstance.py", line 733, in _execute_callable
    return ExecutionCallableRunner(
           ^^^^^^^^^^^^^^^^^^^^^^^^
  File "/home/airflow/.local/lib/python3.12/site-packages/airflow/utils/operator_helpers.py", line 252, in run
    return self.func(*args, **kwargs)
           ^^^^^^^^^^^^^^^^^^^^^^^^^^
  File "/home/airflow/.local/lib/python3.12/site-packages/airflow/models/baseoperator.py", line 417, in wrapper
    return func(self, *args, **kwargs)
           ^^^^^^^^^^^^^^^^^^^^^^^^^^^
  File "/home/airflow/.local/lib/python3.12/site-packages/airflow/decorators/base.py", line 266, in execute
    return_value = super().execute(context)
                   ^^^^^^^^^^^^^^^^^^^^^^^^
  File "/home/airflow/.local/lib/python3.12/site-packages/airflow/models/baseoperator.py", line 417, in wrapper
    return func(self, *args, **kwargs)
           ^^^^^^^^^^^^^^^^^^^^^^^^^^^
  File "/home/airflow/.local/lib/python3.12/site-packages/airflow/operators/python.py", line 238, in execute
    return_value = self.execute_callable()
                   ^^^^^^^^^^^^^^^^^^^^^^^
  File "/home/airflow/.local/lib/python3.12/site-packages/airflow/operators/python.py", line 256, in execute_callable
    return runner.run(*self.op_args, **self.op_kwargs)
           ^^^^^^^^^^^^^^^^^^^^^^^^^^^^^^^^^^^^^^^^^^^
  File "/home/airflow/.local/lib/python3.12/site-packages/airflow/utils/operator_helpers.py", line 252, in run
    return self.func(*args, **kwargs)
           ^^^^^^^^^^^^^^^^^^^^^^^^^^
  File "/opt/airflow/dags/complete_dag.py", line 155, in find_reason_for_unanswered
    hook.run(sql)
  File "/home/airflow/.local/lib/python3.12/site-packages/airflow/providers/common/sql/hooks/sql.py", line 489, in run
    self._run_command(cur, sql_statement, parameters)
  File "/home/airflow/.local/lib/python3.12/site-packages/airflow/providers/common/sql/hooks/sql.py", line 549, in _run_command
    cur.execute(sql_statement)
psycopg2.errors.UndefinedColumn: column "busy" does not exist
LINE 1: UPDATE user_details SET status = busy, modified_on_utc = now...
                                         ^

[2024-12-10T08:11:27.327+0000] {taskinstance.py:1225} INFO - Marking task as FAILED. dag_id=call_9868205040_2024-12-10T08-09-42-184987Z, task_id=find_reason_for_unanswered, run_id=scheduled__2024-12-10T08:09:42.184987+00:00, execution_date=20241210T080942, start_date=20241210T081127, end_date=20241210T081127
[2024-12-10T08:11:27.327+0000] {taskinstance.py:1563} INFO - Executing callback at index 0: task_failure_alert
[2024-12-10T08:11:27.336+0000] {warnings.py:112} WARNING - /home/***/.local/lib/python3.12/site-packages/***/utils/email.py:155: RemovedInAirflow3Warning: Fetching SMTP credentials from configuration variables will be deprecated in a future release. Please set credentials using a connection instead.
  send_mime_email(e_from=mail_from, e_to=recipients, mime_msg=msg, conn_id=conn_id, dryrun=dryrun)

[2024-12-10T08:11:27.336+0000] {email.py:272} INFO - Email alerting: attempt 1
[2024-12-10T08:11:28.954+0000] {email.py:283} INFO - Sent an alert email to ['abhinandan.shrestha@wiseyak.com']
[2024-12-10T08:11:30.824+0000] {taskinstance.py:340} INFO - ::group::Post task execution logs
[2024-12-10T08:11:30.824+0000] {standard_task_runner.py:124} ERROR - Failed to execute job 360 for task find_reason_for_unanswered (column "busy" does not exist
LINE 1: UPDATE user_details SET status = busy, modified_on_utc = now...
                                         ^
; 2016)
Traceback (most recent call last):
  File "/home/airflow/.local/lib/python3.12/site-packages/airflow/task/task_runner/standard_task_runner.py", line 117, in _start_by_fork
    ret = args.func(args, dag=self.dag)
          ^^^^^^^^^^^^^^^^^^^^^^^^^^^^^
  File "/home/airflow/.local/lib/python3.12/site-packages/airflow/cli/cli_config.py", line 49, in command
    return func(*args, **kwargs)
           ^^^^^^^^^^^^^^^^^^^^^
  File "/home/airflow/.local/lib/python3.12/site-packages/airflow/utils/cli.py", line 116, in wrapper
    return f(*args, **kwargs)
           ^^^^^^^^^^^^^^^^^^
  File "/home/airflow/.local/lib/python3.12/site-packages/airflow/cli/commands/task_command.py", line 483, in task_run
    task_return_code = _run_task_by_selected_method(args, _dag, ti)
                       ^^^^^^^^^^^^^^^^^^^^^^^^^^^^^^^^^^^^^^^^^^^^
  File "/home/airflow/.local/lib/python3.12/site-packages/airflow/cli/commands/task_command.py", line 256, in _run_task_by_selected_method
    return _run_raw_task(args, ti)
           ^^^^^^^^^^^^^^^^^^^^^^^
  File "/home/airflow/.local/lib/python3.12/site-packages/airflow/cli/commands/task_command.py", line 341, in _run_raw_task
    return ti._run_raw_task(
           ^^^^^^^^^^^^^^^^^
  File "/home/airflow/.local/lib/python3.12/site-packages/airflow/utils/session.py", line 97, in wrapper
    return func(*args, session=session, **kwargs)
           ^^^^^^^^^^^^^^^^^^^^^^^^^^^^^^^^^^^^^^
  File "/home/airflow/.local/lib/python3.12/site-packages/airflow/models/taskinstance.py", line 3005, in _run_raw_task
    return _run_raw_task(
           ^^^^^^^^^^^^^^
  File "/home/airflow/.local/lib/python3.12/site-packages/airflow/models/taskinstance.py", line 273, in _run_raw_task
    TaskInstance._execute_task_with_callbacks(
  File "/home/airflow/.local/lib/python3.12/site-packages/airflow/models/taskinstance.py", line 3159, in _execute_task_with_callbacks
    result = self._execute_task(context, task_orig)
             ^^^^^^^^^^^^^^^^^^^^^^^^^^^^^^^^^^^^^^
  File "/home/airflow/.local/lib/python3.12/site-packages/airflow/models/taskinstance.py", line 3183, in _execute_task
    return _execute_task(self, context, task_orig)
           ^^^^^^^^^^^^^^^^^^^^^^^^^^^^^^^^^^^^^^^
  File "/home/airflow/.local/lib/python3.12/site-packages/airflow/models/taskinstance.py", line 767, in _execute_task
    result = _execute_callable(context=context, **execute_callable_kwargs)
             ^^^^^^^^^^^^^^^^^^^^^^^^^^^^^^^^^^^^^^^^^^^^^^^^^^^^^^^^^^^^^
  File "/home/airflow/.local/lib/python3.12/site-packages/airflow/models/taskinstance.py", line 733, in _execute_callable
    return ExecutionCallableRunner(
           ^^^^^^^^^^^^^^^^^^^^^^^^
  File "/home/airflow/.local/lib/python3.12/site-packages/airflow/utils/operator_helpers.py", line 252, in run
    return self.func(*args, **kwargs)
           ^^^^^^^^^^^^^^^^^^^^^^^^^^
  File "/home/airflow/.local/lib/python3.12/site-packages/airflow/models/baseoperator.py", line 417, in wrapper
    return func(self, *args, **kwargs)
           ^^^^^^^^^^^^^^^^^^^^^^^^^^^
  File "/home/airflow/.local/lib/python3.12/site-packages/airflow/decorators/base.py", line 266, in execute
    return_value = super().execute(context)
                   ^^^^^^^^^^^^^^^^^^^^^^^^
  File "/home/airflow/.local/lib/python3.12/site-packages/airflow/models/baseoperator.py", line 417, in wrapper
    return func(self, *args, **kwargs)
           ^^^^^^^^^^^^^^^^^^^^^^^^^^^
  File "/home/airflow/.local/lib/python3.12/site-packages/airflow/operators/python.py", line 238, in execute
    return_value = self.execute_callable()
                   ^^^^^^^^^^^^^^^^^^^^^^^
  File "/home/airflow/.local/lib/python3.12/site-packages/airflow/operators/python.py", line 256, in execute_callable
    return runner.run(*self.op_args, **self.op_kwargs)
           ^^^^^^^^^^^^^^^^^^^^^^^^^^^^^^^^^^^^^^^^^^^
  File "/home/airflow/.local/lib/python3.12/site-packages/airflow/utils/operator_helpers.py", line 252, in run
    return self.func(*args, **kwargs)
           ^^^^^^^^^^^^^^^^^^^^^^^^^^
  File "/opt/airflow/dags/complete_dag.py", line 155, in find_reason_for_unanswered
    hook.run(sql)
  File "/home/airflow/.local/lib/python3.12/site-packages/airflow/providers/common/sql/hooks/sql.py", line 489, in run
    self._run_command(cur, sql_statement, parameters)
  File "/home/airflow/.local/lib/python3.12/site-packages/airflow/providers/common/sql/hooks/sql.py", line 549, in _run_command
    cur.execute(sql_statement)
psycopg2.errors.UndefinedColumn: column "busy" does not exist
LINE 1: UPDATE user_details SET status = busy, modified_on_utc = now...
                                         ^

[2024-12-10T08:11:30.870+0000] {local_task_job_runner.py:266} INFO - Task exited with return code 1
[2024-12-10T08:11:30.881+0000] {taskinstance.py:3895} INFO - 0 downstream tasks scheduled from follow-on schedule check
[2024-12-10T08:11:30.883+0000] {local_task_job_runner.py:245} INFO - ::endgroup::
